异常处理
    生成异常信息
        1. fmt.Errorf("error msg")
        2. errors.New("error msg")
    终止程序
        1. 系统自动终止
        2. panic("err msg") // 手动终止
    可以配合defer和recover来捕获异常,但是必须在panic抛出异常之前定义
    defer无论在函数正常或是异常都会执行
    defer的内容在当前函数结束之后执行（如果有return，就是在return之前执行）
    多个defer函数是一个栈的形式，先进后出

    panic vs. os.Exit
        os.Exit 退出时不会调⽤ defer 指定的函数
        os.Exit 退出时不输出当前调⽤栈信息

    recover可以捕获panic异常
    recover只能在defer调用中使用，获取panic的值
        defer func() {
            if err: = recover(); err != nil {
                fmt.Println(err)
            }
        }()
    同一个函数如果有多个终止异常,只有第一个会被捕获

error 类型实现了 error 接⼝
    type error interface {
        Error() string
    }

可以通过 errors.New 来快速创建错误实例
    errors.New("n must be in the range [0,100]")

最佳实践
    定义不同的错误变量，以便于判断错误类型
    及早失败，避免嵌套！
    var LessThanTwoError error = errors.New("n must be greater than 2") 
    var GreaterThanHundredError error = errors.New("n must be less than 100")
    …
    func TestGetFibonacci(t *testing.T) {
        var list []int 
        list, err := GetFibonacci(-10) if err == LessThanTwoError { 
            t.Error("Need a larger number") 
        }

        if err == GreaterThanHundredError { 
            t.Error("Need a larger number") 
        }
        …
    }

